// https://atcoder.jp/contests/arc089/tasks/arc089_a

#include "algorithm"
#include "cmath"
#include "functional"
#include "iostream"
#include "numeric"
#include "queue"
#include "set"
#include "vector"
#define rep(i, to) for (ll i = 0; i < (to); ++i)
#define repf(i, from, to) for (ll i = from; i < (to); ++i)
#define repr(i, from) for (ll i = from - 1; i >= 0; --i)
#define all(vec) vec.begin(), vec.end()
#define fi first
#define se second
using namespace std;
typedef long long ll;
template <typename T>
using V = vector<T>;
using VL = V<ll>;
using VVL = V<VL>;
template <typename T, typename U>
using P = pair<T, U>;
using PL = P<ll, ll>;
using VPL = V<PL>;
template <typename T>
inline bool chmax(T& a, T b);
template <typename T>
inline bool chmin(T& a, T b);
void print_ints(vector<ll> v);
template <typename T>
void drop(T a);

const ll INF = 1e18;

void solve() {
  ll N;
  cin >> N;

  ll cur_t = 0;
  ll cur_x = 0;
  ll cur_y = 0;

  rep(i, N) {
    ll t, x, y;
    cin >> t >> x >> y;

    ll diff_t = t - cur_t;
    ll diff_p = abs(x - cur_x) + abs(y - cur_y);

    if (diff_p > diff_t) drop("No");
    if (diff_p % 2 != diff_t % 2) drop("No");

    cur_t = t;
    cur_x = x;
    cur_y = y;
  }

  cout << "Yes" << endl;
}

struct exit_exception : public std::exception {
  const char* what() const throw() { return "Exited"; }
};

#ifndef TEST
int main() {
  cin.tie(0);
  ios::sync_with_stdio(false);

  try {
    solve();
  } catch (exit_exception& e) {
  }

  return 0;
}
#endif

template <typename T>
inline bool chmax(T& a, T b) {
  if (a < b) {
    a = b;
    return 1;
  }
  return 0;
}

template <typename T>
inline bool chmin(T& a, T b) {
  if (a > b) {
    a = b;
    return 1;
  }
  return 0;
}

void print_ints(vector<ll> v) {
  rep(i, v.size()) {
    if (i > 0) {
      cout << " ";
    }

    cout << v[i];
  }

  cout << endl;
}

template <typename T>
void drop(T res) {
  cout << res << endl;
  throw exit_exception();
}
